<?xml version="1.0"?>

<!-- Copyright (C) 2023  Miguel Ángel González Santamarta

This program is free software: you can redistribute it and/or modify
it under the terms of the GNU General Public License as published by
the Free Software Foundation, either version 3 of the License, or
(at your option) any later version.

This program is distributed in the hope that it will be useful,
but WITHOUT ANY WARRANTY; without even the implied warranty of
MERCHANTABILITY or FITNESS FOR A PARTICULAR PURPOSE.  See the
GNU General Public License for more details.

You should have received a copy of the GNU General Public License
along with this program.  If not, see <https://www.gnu.org/licenses/>. -->

<robot name="wheel" xmlns:xacro="http://www.ros.org/wiki/xacro">
    
    <xacro:property name="M_PI" value="3.1415926535897931" />
    <!-- Wheels -->
    <xacro:property name="wheel_radius" value="0.076" /> 
    <xacro:property name="wheel_height" value="0.050" />
    <xacro:property name="wheel_mass" value="1.0" /> <!-- in kg-->
 
 
    <xacro:macro name="cylinder_inertia" params="m r h">
        <inertia    ixx="${m*(3*r*r+h*h)/12}" ixy = "0" ixz = "0"
                    iyy="${m*(3*r*r+h*h)/12}" iyz = "0"
                    izz="${m*r*r/2}" /> 
    </xacro:macro>
 
    <xacro:macro name="rubber_wheel" params="prefix parent *origin reflect hq">
  
    <!--WHEEL TIRE -->
    <joint name="${prefix}_wheel_joint" type="continuous">
        <parent link="${parent}"/>
        <child link="${prefix}_wheel_link"/>
        <xacro:insert_block name="origin" />
        <axis xyz="0 1 0" rpy="0 0 0" />
        <limit effort="100" velocity="100"/>
        <joint_properties damping="0.0" friction="0.0"/>
    </joint>
  
    <link name="${prefix}_wheel_link">
        <visual>
        <!-- HIGH RESOLUTION WHEELS -->
        <xacro:if value="${hq}">
            <origin xyz="0 0 0" rpy="0 0 0" />
            <geometry>     
                <xacro:if value="${reflect}">
                    <mesh filename="package://rb1_description/meshes/wheels/wheel_rubber_6inch.dae" />
                </xacro:if>
                <xacro:unless value="${reflect}">
                    <mesh filename="package://rb1_description/meshes/wheels/wheel_rubber_6inch.dae" />
                </xacro:unless>
            </geometry>         
        </xacro:if>
        <!-- LOW RESOLUTION WHEELS -->
        <xacro:unless value="${hq}">
            <origin xyz="0 0 0" rpy="${M_PI/2} 0 0" />
            <geometry>           
                <cylinder length="${wheel_height}" radius="${wheel_radius}" />
            </geometry>      
        </xacro:unless>
        </visual>
      
      <collision>
        <origin xyz="0 0 0" rpy="0 0 0" />
        <geometry>
          <mesh filename="package://rb1_description/meshes/wheels/wheel_rubber_6inch.dae" />
        </geometry>
      </collision>
   
      <inertial>
        <mass value="${wheel_mass}" />
        <origin xyz="0 0 0" rpy="${M_PI/2} 0 0"  />
        <xacro:cylinder_inertia  m="${wheel_mass}" r="${wheel_radius}" h="${wheel_height}" />
        <!--inertia  ixx="0.000235075" ixy="0.0"  ixz="0.0"  iyy="0.000235075"  iyz="0.0"  izz="0.00039015" /-->
      </inertial>

    </link>

    <gazebo reference="${prefix}_wheel_link">
			<mu1 value="100.0"/>
			<mu2 value="100.0"/>
			<kp value="10000000.0" />
			<kd value="1.0" />
			<fdir1 value="1 0 0"/>
      <material>Gazebo/Yellow</material>
      <turnGravityOff>false</turnGravityOff>
    </gazebo>

  </xacro:macro>

</robot>
